<?xml version='1.0' encoding='utf-8'?>
<robot name="lego_single_unit">

    <link name="link0">
      <inertial>
        <origin xyz="0 0 0" rpy="0 0 0" />
        <mass value="0.001" />
        <inertia ixx="0.01" iyy="0.01" izz="0.01" ixy="0" ixz="0" iyz="0" />
      </inertial>
    </link>
    <link name="link1">
      <inertial>
        <origin xyz="0 0 0" rpy="0 0 0" />
        <mass value="1e-10" />
        <inertia ixx="1e-10" iyy="1e-10" izz="1e-10" ixy="0" ixz="0" iyz="0" />
      </inertial>
    </link>
    <link name="link2">
      <inertial>
        <origin xyz="0 0 0" rpy="0 0 0" />
        <mass value="1e-10" />
        <inertia ixx="1e-10" iyy="1e-10" izz="1e-10" ixy="0" ixz="0" iyz="0" />
      </inertial>
    </link>
    <link name="link3">
      <inertial>
        <origin xyz="0 0 0" rpy="0 0 0" />
        <mass value="1e-10" />
        <inertia ixx="1e-10" iyy="1e-10" izz="1e-10" ixy="0" ixz="0" iyz="0" />
      </inertial>
    </link>
      <link name="link4">
      <inertial>
        <origin xyz="0 0 0" rpy="0 0 0" />
        <mass value="1e-10" />
        <inertia ixx="1e-10" iyy="1e-10" izz="1e-10" ixy="0" ixz="0" iyz="0" />
      </inertial>
    </link>
    <link name="link5">
      <inertial>
        <origin xyz="0 0 0" rpy="0 0 0" />
        <mass value="1e-10" />
        <inertia ixx="1e-10" iyy="1e-10" izz="1e-10" ixy="0" ixz="0" iyz="0" />
      </inertial>
    </link>
    <link name="link6">
      <inertial>
        <origin xyz="0 0 0" rpy="0 0 0" />
        <mass value="0.004" />
        <inertia ixx="1e-2" iyy="1e-2" izz="1e-2" ixy="0" ixz="0" iyz="0" />
      </inertial>
      <!-- <visual>
        <origin xyz="0 0 0.008" rpy="0 0 0" />
        <geometry>
          <box size="0.0199975 0.0119975 0.016" />
        </geometry> 
      </visual> -->
      <collision>
        <!-- <origin xyz="0 0 0" rpy="0 0 0" /> -->
        <origin xyz="0 0 0.008" rpy="0 0 0" />
        <geometry>
          <!-- <mesh filename="../../../model/test_objects/meshes/visual/cup.obj"/> -->
          <box size="0.0199975 0.0119975 0.016" />
        </geometry>
      </collision> 
    </link>

    <link name="link7">
      <inertial>
        <origin xyz="0 0 0" rpy="0 0 0" />
        <mass value="0.004" />
        <inertia ixx="1e-2" iyy="1e-2" izz="1e-2" ixy="0" ixz="0" iyz="0" />
      </inertial>
      <!-- <visual>
         <origin xyz="0 0 0" rpy="0 0 0" />
        <geometry>
          <box size="0.0119975 0.0199975 0.016" />
        </geometry>
      </visual> -->
      <collision>
        <origin xyz="0 0 0" rpy="0 0 0" />
        <geometry>
          <box size="0.0119975 0.0199975 0.016" />
        </geometry>
      </collision>
    </link>

    <link name="link8">
      <inertial>
        <origin xyz="0 0 0" rpy="0 0 0" />
        <mass value="0.004" />
        <inertia ixx="1e-2" iyy="1e-2" izz="1e-2" ixy="0" ixz="0" iyz="0" />
      </inertial>
      <!-- <visual>
        <origin xyz="0 0 0" rpy="0 0 0" />
        <geometry>
          <box size="0.0199975 0.0119975 0.016" />
        </geometry>
      </visual> -->
      <collision>
        <origin xyz="0 0 0" rpy="0 0 0" />
        <geometry>
          <box size="0.0199975 0.0119975 0.016" />
        </geometry>
      </collision>
    </link>
    <link name="link9">
      <inertial>
        <origin xyz="0 0 0" rpy="0 0 0" />
        <mass value="0.004" />
        <inertia ixx="1e-2" iyy="1e-2" izz="1e-2" ixy="0" ixz="0" iyz="0" />
      </inertial>
      <!-- <visual>
        <origin xyz="0 0 0" rpy="0 0 0" />
        <geometry>
          <box size="0.0119975 0.0199975 0.016"/>
        </geometry>
      </visual> -->
      <collision>
        <origin xyz="0 0 0" rpy="0 0 0" />
        <geometry>
          <box size="0.0119975 0.0199975 0.016"/>
        </geometry>
      </collision>
    </link>
    <link name="link10">
      <inertial>
        <origin xyz="0 0 0" rpy="0 0 0" />
        <mass value="0.001" />
        <inertia ixx="1e-2" iyy="1e-2" izz="1e-2" ixy="0" ixz="0" iyz="0" />
      </inertial>
      <!-- <visual>
        <origin xyz="0 0 0" rpy="0 0 0" />
        <geometry>
          <box size="0.032 0.032 0.003" />
        </geometry>
      </visual> -->
      <collision>
        <origin xyz="0 0 0" rpy="0 0 0" />
        <geometry>
          <box size="0.032 0.032 0.003" />
        </geometry>
      </collision>
    </link>
    
    <link name="link11">
      <inertial>
        <origin xyz="0 0 0" rpy="0 0 0" />
        <mass value="0.001" />
        <inertia ixx="1e-2" iyy="1e-2" izz="1e-2" ixy="0" ixz="0" iyz="0" />
      </inertial>
      <!-- <visual>
        <origin xyz="0 0 0" rpy="0 0 0" />
        <geometry>
          <box size="0.006 0.006 0.004" />
        </geometry>
      </visual> -->
      <visual>
        <origin xyz="0 0 -0.022" rpy="0 0 0" />
        <geometry>
            <mesh filename="meshes/visual/legoSingleUnitColor.obj" scale="1.0 1.0 1.0"/>
        </geometry>
      </visual>
      <collision>
        <origin xyz="0 0 0" rpy="0 0 0" />
        <geometry>
          <box size="0.006 0.006 0.004" />
        </geometry>
      </collision>
    </link>
  
    <joint name="joint1" type="prismatic">
      <origin xyz="0 0 0" rpy="0 0 0"/>
      <parent link="link0"/>
      <child link="link1"/>
      <axis xyz="0 0 1"/>
      <limit effort="21.3" lower="-100" upper="100" velocity="21.3"/>
    </joint>
    <joint name="joint2" type="prismatic">
      <origin xyz="0 0 0" rpy="0 0 0"/>
      <parent link="link1"/>
      <child link="link2"/>
      <axis xyz="0 1 0"/>
      <limit effort="21.3" lower="-100" upper="100" velocity="21.3"/>
    </joint>
    <joint name="joint3" type="prismatic">
      <origin xyz="0 0 0" rpy="0 0 0"/>
      <parent link="link2"/>
      <child link="link3"/>
      <axis xyz="1 0 0"/>
      <limit effort="21.3" lower="-100" upper="100" velocity="21.3"/>
    </joint>
    <joint name="joint4" type="revolute">
      <origin xyz="0 0 0" rpy="0 0 0"/>
      <parent link="link3"/>
      <child link="link4"/>
        <axis xyz="1 0 0"/>
      <limit effort="21.3" lower="0" upper="6.28" velocity="21.3"/>
    </joint>
    <joint name="joint5" type="revolute">
      <origin xyz="0 0 0" rpy="0 0 0"/>
      <parent link="link4"/>
      <child link="link5"/>
        <axis xyz="0 1 0"/>
      <limit effort="21.3" lower="0" upper="6.28" velocity="21.3"/>
    </joint>
    <joint name="joint6" type="revolute">
      <origin xyz="-0.004 -0.0100125 0" rpy="0 0 0"/>
      <parent link="link5"/>
      <child link="link6"/>
        <axis xyz="0 0 1"/>
      <limit effort="21.3" lower="0" upper="6.28" velocity="21.3"/>
    </joint>
<!--     <joint name="joint4" type="spherical">
      <origin xyz="0 0 0" rpy="0 0 0"/>
      <parent link="link3"/>
      <child link="link4"/>
      <limit effort="100" lower="-100" upper="100" velocity="100"/>
    </joint> -->

   <joint name="joint7" type="fixed"> 
      <origin xyz="0.004 0.0160025 0.008" rpy="0 0 0" />
      <parent link="link6"/>
      <child link="link7"/>
    </joint> 
    <joint name="joint8" type="fixed">
      <origin xyz="-0.0160025 0.004 0" rpy="0 0 0" />
      <parent link="link7"/>
      <child link="link8"/>
    </joint>
    <joint name="joint9" type="fixed">
      <origin xyz="-0.004 -0.0160025 0" rpy="0 0 0" />
      <parent link="link8"/>
      <child link="link9"/>
    </joint>
    <joint name="joint10" type="fixed">
      <origin xyz="0.01000375 0.00600375 0.01" rpy="0 0 0" />
      <parent link="link9"/>
      <child link="link10"/>
    </joint>
    <joint name="joint11" type="fixed">
      <origin xyz="0 0 0.004" rpy="0 0 0" />
      <parent link="link10"/>
      <child link="link11"/>
    </joint>
</robot>

</xml>